2020-10-07 18:38:30,928 INFO: Microblog startup [in c:\python\flask2\venv\app\__init__.py:76]
2020-10-07 18:41:18,106 ERROR: Exception on / [GET] [in c:\python\flask2\venv\lib\site-packages\flask\app.py:1891]
Traceback (most recent call last):
  File "c:\python\flask2\venv\lib\site-packages\flask\app.py", line 2447, in wsgi_app
    response = self.full_dispatch_request()
  File "c:\python\flask2\venv\lib\site-packages\flask\app.py", line 1952, in full_dispatch_request
    rv = self.handle_user_exception(e)
  File "c:\python\flask2\venv\lib\site-packages\flask\app.py", line 1821, in handle_user_exception
    reraise(exc_type, exc_value, tb)
  File "c:\python\flask2\venv\lib\site-packages\flask\_compat.py", line 39, in reraise
    raise value
  File "c:\python\flask2\venv\lib\site-packages\flask\app.py", line 1948, in full_dispatch_request
    rv = self.preprocess_request()
  File "c:\python\flask2\venv\lib\site-packages\flask\app.py", line 2242, in preprocess_request
    rv = func()
  File "c:\python\flask2\venv\app\main\routes.py", line 19, in before_request
    g.locale = str(get_locale())
NameError: name 'get_locale' is not defined
2020-10-07 18:42:28,303 INFO: Microblog startup [in c:\python\flask2\venv\app\__init__.py:76]
2020-10-07 18:42:31,038 ERROR: Exception on /auth/login [GET] [in c:\python\flask2\venv\lib\site-packages\flask\app.py:1891]
Traceback (most recent call last):
  File "c:\python\flask2\venv\lib\site-packages\flask\app.py", line 2447, in wsgi_app
    response = self.full_dispatch_request()
  File "c:\python\flask2\venv\lib\site-packages\flask\app.py", line 1952, in full_dispatch_request
    rv = self.handle_user_exception(e)
  File "c:\python\flask2\venv\lib\site-packages\flask\app.py", line 1821, in handle_user_exception
    reraise(exc_type, exc_value, tb)
  File "c:\python\flask2\venv\lib\site-packages\flask\_compat.py", line 39, in reraise
    raise value
  File "c:\python\flask2\venv\lib\site-packages\flask\app.py", line 1950, in full_dispatch_request
    rv = self.dispatch_request()
  File "c:\python\flask2\venv\lib\site-packages\flask\app.py", line 1936, in dispatch_request
    return self.view_functions[rule.endpoint](**req.view_args)
  File "c:\python\flask2\venv\app\auth\routes.py", line 32, in login
    return render_template('auth/login.html', title='Sign In', form=form)
  File "c:\python\flask2\venv\lib\site-packages\flask\templating.py", line 137, in render_template
    return _render(
  File "c:\python\flask2\venv\lib\site-packages\flask\templating.py", line 120, in _render
    rv = template.render(context)
  File "c:\python\flask2\venv\lib\site-packages\jinja2\environment.py", line 1090, in render
    self.environment.handle_exception()
  File "c:\python\flask2\venv\lib\site-packages\jinja2\environment.py", line 832, in handle_exception
    reraise(*rewrite_traceback_stack(source=source))
  File "c:\python\flask2\venv\lib\site-packages\jinja2\_compat.py", line 28, in reraise
    raise value.with_traceback(tb)
  File "c:\python\flask2\venv\app\templates\auth\login.html", line 1, in top-level template code
    {% extends 'base.html' %}
  File "c:\python\flask2\venv\lib\site-packages\jinja2\environment.py", line 832, in handle_exception
    reraise(*rewrite_traceback_stack(source=source))
  File "c:\python\flask2\venv\lib\site-packages\jinja2\_compat.py", line 28, in reraise
    raise value.with_traceback(tb)
  File "c:\python\flask2\venv\app\templates\base.html", line 27, in template
    action="{{ url_for('main.search')">
jinja2.exceptions.TemplateSyntaxError: expected token 'end of print statement', got 'string'
2020-10-07 18:43:34,141 INFO: Microblog startup [in c:\python\flask2\venv\app\__init__.py:76]
2020-10-07 18:43:51,273 ERROR: Exception on / [GET] [in c:\python\flask2\venv\lib\site-packages\flask\app.py:1891]
Traceback (most recent call last):
  File "c:\python\flask2\venv\lib\site-packages\flask\app.py", line 2447, in wsgi_app
    response = self.full_dispatch_request()
  File "c:\python\flask2\venv\lib\site-packages\flask\app.py", line 1952, in full_dispatch_request
    rv = self.handle_user_exception(e)
  File "c:\python\flask2\venv\lib\site-packages\flask\app.py", line 1821, in handle_user_exception
    reraise(exc_type, exc_value, tb)
  File "c:\python\flask2\venv\lib\site-packages\flask\_compat.py", line 39, in reraise
    raise value
  File "c:\python\flask2\venv\lib\site-packages\flask\app.py", line 1948, in full_dispatch_request
    rv = self.preprocess_request()
  File "c:\python\flask2\venv\lib\site-packages\flask\app.py", line 2242, in preprocess_request
    rv = func()
  File "c:\python\flask2\venv\app\main\routes.py", line 16, in before_request
    g.search_form = SearchForm()
  File "c:\python\flask2\venv\lib\site-packages\wtforms\form.py", line 208, in __call__
    return type.__call__(cls, *args, **kwargs)
  File "c:\python\flask2\venv\app\main\forms.py", line 36, in __init__
    super(SearchForm, self).__init__(*args, **kwarg)
NameError: name 'kwarg' is not defined
2020-10-07 18:44:19,947 INFO: Microblog startup [in c:\python\flask2\venv\app\__init__.py:76]
2020-10-07 18:44:24,720 ERROR: Exception on / [GET] [in c:\python\flask2\venv\lib\site-packages\flask\app.py:1891]
Traceback (most recent call last):
  File "c:\python\flask2\venv\lib\site-packages\flask\app.py", line 2447, in wsgi_app
    response = self.full_dispatch_request()
  File "c:\python\flask2\venv\lib\site-packages\flask\app.py", line 1952, in full_dispatch_request
    rv = self.handle_user_exception(e)
  File "c:\python\flask2\venv\lib\site-packages\flask\app.py", line 1821, in handle_user_exception
    reraise(exc_type, exc_value, tb)
  File "c:\python\flask2\venv\lib\site-packages\flask\_compat.py", line 39, in reraise
    raise value
  File "c:\python\flask2\venv\lib\site-packages\flask\app.py", line 1948, in full_dispatch_request
    rv = self.preprocess_request()
  File "c:\python\flask2\venv\lib\site-packages\flask\app.py", line 2242, in preprocess_request
    rv = func()
  File "c:\python\flask2\venv\app\main\routes.py", line 16, in before_request
    g.search_form = SearchForm()
NameError: name 'g' is not defined
2020-10-07 18:44:46,648 INFO: Microblog startup [in c:\python\flask2\venv\app\__init__.py:76]
2020-10-07 20:20:40,836 INFO: Microblog startup [in C:\Python\flask2\venv\app\__init__.py:76]
2020-10-07 20:23:05,408 INFO: Microblog startup [in C:\Python\flask2\venv\app\__init__.py:76]
2020-10-07 21:13:25,686 INFO: Microblog startup [in C:\Python\flask2\venv\app\__init__.py:81]
2020-10-07 21:28:07,269 INFO: Microblog startup [in C:\Python\flask2\venv\app\__init__.py:81]
2020-10-07 21:41:09,671 INFO: Microblog startup [in C:\Python\flask2\venv\app\__init__.py:81]
2020-10-08 00:27:15,073 INFO: Microblog startup [in C:\Python\flask2\venv\app\__init__.py:80]
2020-10-08 00:27:33,873 ERROR: Exception on /auth/login [POST] [in c:\python\flask2\venv\lib\site-packages\flask\app.py:1891]
Traceback (most recent call last):
  File "c:\python\flask2\venv\lib\site-packages\sqlalchemy\util\_collections.py", line 1020, in __call__
    return self.registry[key]
KeyError: 7992

During handling of the above exception, another exception occurred:

Traceback (most recent call last):
  File "c:\python\flask2\venv\lib\site-packages\flask\app.py", line 2447, in wsgi_app
    response = self.full_dispatch_request()
  File "c:\python\flask2\venv\lib\site-packages\flask\app.py", line 1952, in full_dispatch_request
    rv = self.handle_user_exception(e)
  File "c:\python\flask2\venv\lib\site-packages\flask\app.py", line 1821, in handle_user_exception
    reraise(exc_type, exc_value, tb)
  File "c:\python\flask2\venv\lib\site-packages\flask\_compat.py", line 39, in reraise
    raise value
  File "c:\python\flask2\venv\lib\site-packages\flask\app.py", line 1950, in full_dispatch_request
    rv = self.dispatch_request()
  File "c:\python\flask2\venv\lib\site-packages\flask\app.py", line 1936, in dispatch_request
    return self.view_functions[rule.endpoint](**req.view_args)
  File "C:\Python\flask2\venv\app\auth\routes.py", line 17, in login
    user = User.query.filter_by(username=form.username.data).first()
  File "c:\python\flask2\venv\lib\site-packages\flask_sqlalchemy\__init__.py", line 514, in __get__
    return type.query_class(mapper, session=self.sa.session())
  File "c:\python\flask2\venv\lib\site-packages\sqlalchemy\orm\scoping.py", line 78, in __call__
    return self.registry()
  File "c:\python\flask2\venv\lib\site-packages\sqlalchemy\util\_collections.py", line 1022, in __call__
    return self.registry.setdefault(key, self.createfunc())
  File "c:\python\flask2\venv\lib\site-packages\sqlalchemy\orm\session.py", line 3286, in __call__
    return self.class_(**local_kw)
  File "c:\python\flask2\venv\lib\site-packages\flask_sqlalchemy\__init__.py", line 138, in __init__
    bind = options.pop('bind', None) or db.engine
  File "c:\python\flask2\venv\lib\site-packages\flask_sqlalchemy\__init__.py", line 943, in engine
    return self.get_engine()
  File "c:\python\flask2\venv\lib\site-packages\flask_sqlalchemy\__init__.py", line 962, in get_engine
    return connector.get_engine()
  File "c:\python\flask2\venv\lib\site-packages\flask_sqlalchemy\__init__.py", line 555, in get_engine
    options = self.get_options(sa_url, echo)
  File "c:\python\flask2\venv\lib\site-packages\flask_sqlalchemy\__init__.py", line 570, in get_options
    self._sa.apply_driver_hacks(self._app, sa_url, options)
  File "c:\python\flask2\venv\lib\site-packages\flask_sqlalchemy\__init__.py", line 883, in apply_driver_hacks
    if sa_url.drivername.startswith('mysql'):
AttributeError: 'NoneType' object has no attribute 'drivername'
2020-10-08 00:29:58,560 INFO: Microblog startup [in C:\Python\flask2\venv\app\__init__.py:80]
